Workbook

Sheet Simulation
B3: Fixed Expenses | C3: 100000
B4: % Based Expenses | C4: 0.25 | E4: Bonus achieve | F4: 0.3
B5: Marketing | C5: 200000
B9: GGR for 0 | C9: =(C3+C5)/(1-(C4+F4)) -> 666666.67
B11: Margin | C11: 0.03
B13: Bets needed | C13: =C9/C11 -> 22222222

Sheet Clean FIN EUR
B1: EBITDA by month | I1: Assuming April as representative of expence %
C2: Month | D2: =E10 -> 46082 | E2: =G10 -> 46113 | F2: =I10 -> 46143
C3: GGR (EUR) | D3: =E11 -> 262967.71 | E3: =G11 -> 243296.01 | F3: =I11 -> 146510.42 | I3: We will need the following GGR for EBITDA 0
C4: All Expenses (EUR) | D4: =E25 -> 307819.85 | E4: =G25 -> 309354.51 | F4: =I25 -> 256584.65 | I4: =(G24+I7)/(1-(H18+J7)) -> 671007
C5: EBITDA (EUR) | D5: =D3-D4 -> -44852.139 | E5: =E3-E4 -> -66058.494 | F5: =F3-F4 -> -110074.23
C6: EBITDA % of GGR | D6: =D5/D3 -> -0.17056139 | E6: =E5/E3 -> -0.27151491 | F6: =F5/F3 -> -0.75130648 | H6: Simulate numbers
C7: Breakeven GGR | D7: =(E24)/(1-(F18+F13)) -> 353520.52 | E7: =(G24)/(1-(H18+H13)) -> 365478.35 | F7: =(I24)/(1-(J18+J13)) -> 386220.04 | H7: Additional spend on marketing | I7: 100000 | J7: 0.3
C8: GGR needed to hit EBITDA ≈ 0 | D8: =D7-D3 -> 90552.811 | E8: =E7-E3 -> 122182.34 | F8: =F7-F3 -> 239709.62
C9: END OF MONTH MXN to EUR | F9: 0.0483 | H9: 0.0488 | J9: 0.0494
C10: Month | E10: 46082 | G10: 46113 | I10: 46143
C11: GGR | E11: =5444466*F9 -> 262967.71 | G11: =4985574*H9 -> 243296.01 | I11: =2965798*J9 -> 146510.42 | L11: 95686
E12: Amount | F12: % of GGR | G12: Amount | H12: % of GGR | I12: Amount | J12: % of GGR
B13: % based expenses | C13: Bonus Achieve | E13: =1444502*F9 -> 69769.447 | F13: =E13/$E$11 -> 0.26531564 | G13: =1011344*H9 -> 49353.587 | H13: =G13/G$11 -> 0.20285407 | I13: =1204728*J9 -> 59513.563 | J13: =I13/I$11 -> 0.40620703
C14: Taxes | E14: ='Calc - opperational'!G6*F9 -> 21905.597 | F14: =E14/$E$11 -> 0.08330147 | G14: ='Calc - opperational'!J6*H9 -> 22242.383 | H14: =G14/G$11 -> 0.091421074 | I14: ='Calc - opperational'!M6*J9 -> 0 | J14: =I14/I$11 -> 0
C15: Providers (direct deals) | E15: ='Calc - opperational'!G11*F9 -> 531.3 | F15: =E15/$E$11 -> 0.0020204002 | G15: ='Calc - opperational'!J11*H9 -> 0 | H15: =G15/G$11 -> 0 | I15: ='Calc - opperational'!J10*J9 -> 2.801474 | J15: =I15/I$11 -> 1.9121329e-05
C16: Payment processing | E16: ='Calc - opperational'!D14*F9 -> 8953.4676 | F16: =E16/$E$11 -> 0.034047784 | G16: ='Calc - opperational'!G14*H9 -> 10965.311 | H16: =G16/G$11 -> 0.045069835 | I16: ='Calc - opperational'!J14*J9 -> 2135.483 | J16: =I16/I$11 -> 0.014575639
C17: Platform+Aggregation | E17: =E11*F17 -> 31556.125 | F17: 0.12 | G17: =G11*H17 -> 29195.521 | H17: 0.12 | I17: =I11*J17 -> 17581.251 | J17: 0.12
B18: Overall % based expenses | E18: =SUM(E14:E17) -> 62946.489 | F18: =E18/$E$11 -> 0.23936965 | G18: =SUM(G14:G17) -> 62403.215 | H18: =G18/G$11 -> 0.25649091 | I18: =SUM(I14:I17) -> 19719.535 | J18: =I18/I$11 -> 0.13459476
B19: Fixed expenses | C19: Payroll | E19: ='Calc - opperational'!D23*F9 -> 76409.52 | F19: =E19/$E$11 -> 0.29056617 | G19: ='Calc - opperational'!G23*H9 -> 48230.731 | H19: =G19/G$11 -> 0.19823889 | I19: ='Calc - opperational'!J23*J9 -> 64207.435 | J19: =I19/I$11 -> 0.43824483
C20: Office | E20: ='Calc - opperational'!D31*F9 -> 10317.807 | F20: =E20/$E$11 -> 0.039236022 | G20: ='Calc - opperational'!G31*H9 -> 11248.013 | H20: =G20/G$11 -> 0.0462318 | I20: ='Calc - opperational'!J31*J9 -> 12634.017 | J20: =I20/I$11 -> 0.086232889
C21: Marketing | E21: ='Calc - opperational'!D42*F9 -> 82355.807 | F21: =E21/$E$11 -> 0.31317841 | G21: ='Calc - opperational'!G42*H9 -> 126419.11 | H21: =G21/G$11 -> 0.5196103 | I21: ='Calc - opperational'!J42*J9 -> 84932.497 | J21: =I21/I$11 -> 0.57970277
C22: Legal | E22: ='Calc - opperational'!D49*F9 -> 679.52546 | F22: =E22/$E$11 -> 0.0025840643 | G22: ='Calc - opperational'!G49*H9 -> 0 | H22: =G22/G$11 -> 0 | I22: ='Calc - opperational'!J49*J9 -> 12416.591 | J22: =I22/I$11 -> 0.08474886
C23: Accounting | E23: ='Calc - opperational'!D52*F9 -> 5341.2512 | F23: =E23/$E$11 -> 0.020311434 | G23: ='Calc - opperational'!G52*H9 -> 11699.847 | H23: =G23/G$11 -> 0.048088938 | I23: ='Calc - opperational'!J52*J9 -> 3161.0131 | J23: =I23/I$11 -> 0.021575347
B24: Overall Fixed expenses | E24: =E23+E22+E21+E20+E19 -> 175103.91 | F24: =E24/$E$11 -> 0.6658761 | G24: =G23+G22+G21+G20+G19 -> 197597.7 | H24: =G24/G$11 -> 0.81216992 | I24: =I23+I22+I21+I20+I19 -> 177351.55 | J24: =I24/I$11 -> 1.2105047
B25: All Expenses | E25: =E24+E18+E13 -> 307819.85 | F25: =E25/$E$11 -> 1.1705614 | G25: =G24+G18+G13 -> 309354.51 | H25: =G25/G$11 -> 1.2715149 | I25: =I24+I18+I13 -> 256584.65 | J25: =I25/I$11 -> 1.7513065

Sheet Clean FIN MXN
B1: EBITDA by month
C2: Month | D2: =E10 -> 46082 | E2: =G10 -> 46113 | F2: =I10 -> 46143
C3: GGR (MXN) | D3: =E11 -> 5444466 | E3: =G11 -> 4985574 | F3: =I11 -> 2965798
C4: All Expenses (MXN) | D4: =E25 -> 6373081.7 | E4: =G25 -> 6339231.7 | F4: =I25 -> 5194021.3
C5: EBITDA (MXN) | D5: =D3-D4 -> -928615.71 | E5: =E3-E4 -> -1353657.7 | F5: =F3-F4 -> -2228223.3
C6: EBITDA % of GGR | D6: =D5/D3 -> -0.17056139 | E6: =E5/E3 -> -0.27151491 | F6: =F5/F3 -> -0.75130648
B9: MXN
C10: Month | E10: 46082 | G10: 46113 | I10: 46143
C11: GGR | E11: 5444466 | G11: 4985574 | I11: 2965798
E12: Amount | F12: % of GGR | G12: Amount | H12: % of GGR | I12: Amount | J12: % of GGR
B13: CRM | C13: Bonus Achieve | E13: 1444502 | F13: =E13/$E$11 -> 0.26531564 | G13: 1011344 | H13: =G13/G$11 -> 0.20285407 | I13: 1204728 | J13: =I13/I$11 -> 0.40620703
B14: % based expenses | C14: Taxes | E14: ='Calc - opperational'!G6 -> 453532.02 | F14: =E14/$E$11 -> 0.08330147 | G14: ='Calc - opperational'!J6 -> 455786.53 | H14: =G14/G$11 -> 0.091421074 | I14: ='Calc - opperational'!M6 -> 0 | J14: =I14/I$11 -> 0
C15: Providers (direct deals) | E15: ='Calc - opperational'!G11 -> 11000 | F15: =E15/$E$11 -> 0.0020204002 | G15: ='Calc - opperational'!J11 -> 0 | H15: =G15/G$11 -> 0 | I15: ='Calc - opperational'!J10 -> 56.71 | J15: =I15/I$11 -> 1.9121329e-05
C16: Payment processing | E16: ='Calc - opperational'!D14 -> 185372 | F16: =E16/$E$11 -> 0.034047784 | G16: ='Calc - opperational'!G14 -> 224699 | H16: =G16/G$11 -> 0.045069835 | I16: ='Calc - opperational'!J14 -> 43228.4 | J16: =I16/I$11 -> 0.014575639
C17: Platform+Aggregation | E17: =E11*F17 -> 653335.92 | F17: 0.12 | G17: =G11*H17 -> 598268.88 | H17: 0.12 | I17: =I11*J17 -> 355895.76 | J17: 0.12
B18: Overall % based expenses | E18: =SUM(E14:E17) -> 1303239.9 | F18: =E18/$E$11 -> 0.23936965 | G18: =SUM(G14:G17) -> 1278754.4 | H18: =G18/G$11 -> 0.25649091 | I18: =SUM(I14:I17) -> 399180.87 | J18: =I18/I$11 -> 0.13459476
B19: Fixed expenses | C19: Payroll | E19: ='Calc - opperational'!D23 -> 1581977.6 | F19: =E19/$E$11 -> 0.29056617 | G19: ='Calc - opperational'!G23 -> 988334.65 | H19: =G19/G$11 -> 0.19823889 | I19: ='Calc - opperational'!J23 -> 1299745.6 | J19: =I19/I$11 -> 0.43824483
C20: Office | E20: ='Calc - opperational'!D31 -> 213619.19 | F20: =E20/$E$11 -> 0.039236022 | G20: ='Calc - opperational'!G31 -> 230492.06 | H20: =G20/G$11 -> 0.0462318 | I20: ='Calc - opperational'!J31 -> 255749.33 | J20: =I20/I$11 -> 0.086232889
C21: Marketing | E21: ='Calc - opperational'!D42 -> 1705089.2 | F21: =E21/$E$11 -> 0.31317841 | G21: ='Calc - opperational'!G42 -> 2590555.6 | H21: =G21/G$11 -> 0.5196103 | I21: ='Calc - opperational'!J42 -> 1719281.3 | J21: =I21/I$11 -> 0.57970277
C22: Legal | E22: ='Calc - opperational'!D49 -> 14068.85 | F22: =E22/$E$11 -> 0.0025840643 | G22: ='Calc - opperational'!G49 -> 0 | H22: =G22/G$11 -> 0 | I22: ='Calc - opperational'!J49 -> 251348 | J22: =I22/I$11 -> 0.08474886
C23: Accounting | E23: ='Calc - opperational'!D52 -> 110584.91 | F23: =E23/$E$11 -> 0.020311434 | G23: ='Calc - opperational'!G52 -> 239750.96 | H23: =G23/G$11 -> 0.048088938 | I23: ='Calc - opperational'!J52 -> 63988.12 | J23: =I23/I$11 -> 0.021575347
B24: Overall Fixed expenses | E24: =E23+E22+E21+E20+E19 -> 3625339.8 | F24: =E24/$E$11 -> 0.6658761 | G24: =G23+G22+G21+G20+G19 -> 4049133.2 | H24: =G24/G$11 -> 0.81216992 | I24: =I23+I22+I21+I20+I19 -> 3590112.4 | J24: =I24/I$11 -> 1.2105047
B25: All Expenses | E25: =E24+E18+E13 -> 6373081.7 | F25: =E25/$E$11 -> 1.1705614 | G25: =G24+G18+G13 -> 6339231.7 | H25: =G25/G$11 -> 1.2715149 | I25: =I24+I18+I13 -> 5194021.3 | J25: =I25/I$11 -> 1.7513065

Sheet Calc - opperational
A1: MXN
B2: Month | D2: 46082 | G2: 46113 | J2: 46143
B3: GGR | D3: 5444466 | G3: 4985574 | J3: 2965798
B4: RM GGR | D4: 1520694 | G4: 1807902 | J4: 1081464
D5: Amount | E5: % of GGR | F5: % of RM GGR | G5: Amount | H5: % of GGR | I5: % of RM GGR | J5: Amount | K5: % of GGR | L5: % of RM GGR
A6: % based expenses | B6: Taxes | D6: =SUM(D7:D9) -> 137785.1 | E6: =D6/$D$3 -> 0.025307367 | F6: =D6/$D$4 -> 0.090606723 | G6: =SUM(G7:G9) -> 453532.02 | H6: =G6/G$3 -> 0.090968867 | I6: =G6/G$4 -> 0.25086095 | J6: =SUM(J7:J9) -> 455786.53 | K6: =J6/J$3 -> 0.15368091 | L6: =J6/J$4 -> 0.42145326
C7: ACE | D7: ='03-2026'!F8 -> 35215.79 | E7: =D7/$D$3 -> 0.0064681807 | F7: =D7/$D$4 -> 0.02315771 | G7: ='04-2026'!F2 -> 53042 | H7: =G7/G$3 -> 0.010639096 | I7: =G7/G$4 -> 0.02933898 | J7: ='05-2026'!F5 -> 55000 | K7: =J7/J$3 -> 0.018544756 | L7: =J7/J$4 -> 0.050856986
C8: Federal Taxes | D8: ='03-2026'!F11 -> 102569.31 | E8: =D8/$D$3 -> 0.018839186 | F8: =D8/$D$4 -> 0.067449013 | G8: ='04-2026'!F7 -> 119986.02 | H8: =G8/G$3 -> 0.024066641 | I8: =G8/G$4 -> 0.066367546 | J8: ='05-2026'!F7 -> 126339.53 | K8: =J8/J$3 -> 0.042598832 | L8: =J8/J$4 -> 0.11682269
C9: ISR | G9: ='04-2026'!F25 -> 280504 | H9: =G9/G$3 -> 0.05626313 | I9: =G9/G$4 -> 0.15515443 | J9: ='05-2026'!F23 -> 274447 | K9: =J9/J$3 -> 0.09253732 | L9: =J9/J$4 -> 0.25377359
B10: Providers (direct deals) | D10: =SUM(D11:D13) -> 0 | E10: =D10/$D$3 -> 0 | F10: =D10/$D$4 -> 0 | G10: =SUM(G11:G13) -> 11000 | H10: =G10/G$3 -> 0.0022063658 | I10: =G10/G$4 -> 0.0060844006 | J10: =SUM(J11:J13) -> 56.71 | K10: =J10/J$3 -> 1.9121329e-05 | L10: =J10/J$4 -> 5.2438176e-05
C11: Amusnet | E11: =D11/$D$3 -> 0 | F11: =D11/$D$4 -> 0 | G11: ='04-2026'!F10 -> 11000 | H11: =G11/G$3 -> 0.0022063658 | I11: =G11/G$4 -> 0.0060844006 | J11: 0 | K11: =J11/J$3 -> 0 | L11: =J11/J$4 -> 0
C12: Skywind | E12: =D12/$D$3 -> 0 | F12: =D12/$D$4 -> 0 | H12: =G12/G$3 -> 0 | I12: =G12/G$4 -> 0 | J12: 56.71 | K12: =J12/J$3 -> 1.9121329e-05 | L12: =J12/J$4 -> 5.2438176e-05
B14: Payment processing | D14: =SUM(D15:D18) -> 185372 | E14: =D14/$D$3 -> 0.034047784 | F14: =D14/$D$4 -> 0.12189961 | G14: =SUM(G15:G18) -> 224699 | H14: =G14/G$3 -> 0.045069835 | I14: =G14/G$4 -> 0.12428716 | J14: =SUM(J15:J18) -> 43228.4 | K14: =J14/J$3 -> 0.014575639 | L14: =J14/J$4 -> 0.039972112
C15: Nuvei SPEI | D15: ='Payment+Assesment'!F21 -> 149204 | E15: =D15/$D$3 -> 0.027404708 | F15: =D15/$D$4 -> 0.098115729 | G15: ='Payment+Assesment'!F23 -> 183619 | H15: =G15/G$3 -> 0.036830062 | I15: =G15/G$4 -> 0.10156469 | J15: ='Payment+Assesment'!L21 -> 0 | K15: =J15/J$3 -> 0 | L15: =J15/J$4 -> 0
C16: Cards | D16: ='Payment+Assesment'!F20 -> 36168 | E16: =D16/$D$3 -> 0.0066430757 | F16: =D16/$D$4 -> 0.023783878 | G16: ='Payment+Assesment'!F22 -> 41080 | H16: =G16/G$3 -> 0.0082397734 | I16: =G16/G$4 -> 0.022722471 | J16: ='Payment+Assesment'!L20 -> 0 | K16: =J16/J$3 -> 0 | L16: =J16/J$4 -> 0
C17: STP Direct | J17: ='Payment+Assesment'!F26+'05-2026'!F10 -> 43228.4 | K17: =J17/J$3 -> 0.014575639 | L17: =J17/J$4 -> 0.039972112
B19: Platform+Aggregation | D19: =SUM(D20:D20) -> 641988.9 | E19: =D19/$D$3 -> 0.11791586 | F19: =D19/$D$4 -> 0.42216837 | G19: =SUM(G20:G20) -> 0 | H19: =G19/G$3 -> 0 | I19: =G19/G$4 -> 0 | J19: =SUM(J20:J20) -> 0 | K19: =J19/J$3 -> 0 | L19: =J19/J$4 -> 0
C20: EGT | D20: ='03-2026'!F40 -> 641988.9 | E20: =D20/$D$3 -> 0.11791586 | F20: =D20/$D$4 -> 0.42216837 | G20: ='03-2026'!I40 -> 0 | H20: =G20/G$3 -> 0 | I20: =G20/G$4 -> 0 | J20: ='03-2026'!L40 -> 0 | K20: =J20/J$3 -> 0 | L20: =J20/J$4 -> 0
A21: Overall % based expenses | D21: =D19+D14+D6 -> 965146 | E21: =D21/$D$3 -> 0.17727101 | F21: =D21/$D$4 -> 0.63467469 | G21: =G19+G14+G6 -> 678231.02 | H21: =G21/G$3 -> 0.1360387 | I21: =G21/G$4 -> 0.37514811 | J21: =J19+J14+J6+J10 -> 499071.64 | K21: =J21/J$3 -> 0.16827567 | L21: =J21/J$4 -> 0.46147781
A22: Fixed expenses
B23: Payroll | D23: =SUM(D24:D30) -> 1581977.6 | E23: =D23/$D$3 -> 0.29056617 | F23: =D23/$D$4 -> 1.0402998 | G23: =SUM(G24:G30) -> 988334.65 | H23: =G23/G$3 -> 0.19823889 | I23: =G23/G$4 -> 0.5466749 | J23: =SUM(J24:J30) -> 1299745.6 | K23: =J23/J$3 -> 0.43824483 | L23: =J23/J$4 -> 1.201839
C24: 1st Half of Month | D24: ='03-2026'!F22 -> 447958.1 | E24: =D24/$D$3 -> 0.082277693 | F24: =D24/$D$4 -> 0.29457478 | G24: ='04-2026'!F17 -> 433242.74 | H24: =G24/G$3 -> 0.08689927 | I24: =G24/G$4 -> 0.2396384 | J24: ='05-2026'!F11 -> 443374.29 | K24: =J24/J$3 -> 0.14949578 | L24: =J24/J$4 -> 0.409976
C25: 2nd Half of Month | D25: ='03-2026'!F26 -> 452464.84 | E25: =D25/$D$3 -> 0.083105458 | F25: =D25/$D$4 -> 0.29753839 | G25: ='04-2026'!F31 -> 439322.47 | H25: =G25/G$3 -> 0.088118734 | I25: =G25/G$4 -> 0.24300126 | J25: ='05-2026'!F27 -> 457938.76 | K25: =J25/J$3 -> 0.15440659 | L25: =J25/J$4 -> 0.42344337
C26: Employee Termination | D26: ='03-2026'!F4 -> 6435.06 | E26: =D26/$D$3 -> 0.0011819451 | F26: =D26/$D$4 -> 0.00423166 | G26: ='03-2026'!I4 -> 0 | H26: =G26/G$3 -> 0 | I26: =G26/G$4 -> 0 | J26: ='03-2026'!L4 -> 0 | K26: =J26/J$3 -> 0 | L26: =J26/J$4 -> 0
C27: FONACOT | D27: ='03-2026'!F6 -> 877 | E27: =D27/$D$3 -> 0.00016108099 | F27: =D27/$D$4 -> 0.00057671037 | G27: ='03-2026'!I6 -> 0 | H27: =G27/G$3 -> 0 | I27: =G27/G$4 -> 0 | J27: ='03-2026'!L6 -> 0 | K27: =J27/J$3 -> 0 | L27: =J27/J$4 -> 0
C28: ISN | D28: ='03-2026'!F20+'03-2026'!F28+'03-2026'!F29 -> 329683 | E28: =D28/$D$3 -> 0.060553781 | F28: =D28/$D$4 -> 0.21679773 | G28: ='04-2026'!F12 -> 36614 | H28: =G28/G$3 -> 0.0073439889 | I28: =G28/G$4 -> 0.020252204 | J28: ='05-2026'!F13 -> 35365 | K28: =J28/J$3 -> 0.011924278 | L28: =J28/J$4 -> 0.032701042
C29: SIPARE | D29: ='03-2026'!F21 -> 344559.64 | E29: =D29/$D$3 -> 0.063286214 | F29: =D29/$D$4 -> 0.22658052 | G29: ='04-2026'!F13 -> 79155.44 | H29: =G29/G$3 -> 0.015876896 | I29: =G29/G$4 -> 0.043783037 | J29: ='05-2026'!F14 -> 363067.59 | K29: =J29/J$3 -> 0.12241818 | L29: =J29/J$4 -> 0.33571861
B31: Office | D31: =SUM(D32:D41) -> 213619.19 | E31: =D31/$D$3 -> 0.039236022 | F31: =D31/$D$4 -> 0.1404748 | G31: =SUM(G32:G41) -> 230492.06 | H31: =G31/G$3 -> 0.0462318 | I31: =G31/G$4 -> 0.12749146 | J31: =SUM(J32:J41) -> 255749.33 | K31: =J31/J$3 -> 0.086232889 | L31: =J31/J$4 -> 0.23648437
C32: Rent | D32: ='03-2026'!F18 -> 148048.48 | E32: =D32/$D$3 -> 0.02719247 | F32: =D32/$D$4 -> 0.097355865 | G32: ='04-2026'!F15 -> 148048.48 | H32: =G32/G$3 -> 0.029695373 | I32: =G32/G$4 -> 0.08188966 | J32: ='05-2026'!F8 -> 148048.48 | K32: =J32/J$3 -> 0.049918599 | L32: =J32/J$4 -> 0.13689636
C33: Maintenance | D33: ='03-2026'!F19 -> 29609.7 | E33: =D33/$D$3 -> 0.0054384948 | F33: =D33/$D$4 -> 0.019471176 | G33: ='04-2026'!F16 -> 29609.7 | H33: =G33/G$3 -> 0.0059390754 | I33: =G33/G$4 -> 0.016377934 | J33: ='05-2026'!F9 -> 29609.7 | K33: =J33/J$3 -> 0.0099837211 | L33: =J33/J$4 -> 0.027379275
C34: Limpieza Renovadora | D34: ='03-2026'!F7 -> 19258.04 | E34: =D34/$D$3 -> 0.003537177 | F34: =D34/$D$4 -> 0.012663981 | G34: ='04-2026'!F6 -> 22111.08 | H34: =G34/G$3 -> 0.0044350119 | I34: =G34/G$4 -> 0.012230243 | J34: ='05-2026'!F17 -> 20684.56 | K34: =J34/J$3 -> 0.0069743658 | L34: =J34/J$4 -> 0.019126443
C35: Vanguardia IT | D35: ='03-2026'!F14+'03-2026'!F37 -> 2780.02 | E35: =D35/$D$3 -> 0.0005106139 | F35: =D35/$D$4 -> 0.0018281258 | G35: ='04-2026'!F5 -> 280.01 | H35: =G35/G$3 -> 5.6164045e-05 | I35: =G35/G$4 -> 0.00015488118 | J35: ='05-2026'!F3 -> 280.01 | K35: =J35/J$3 -> 9.4413038e-05 | L35: =J35/J$4 -> 0.00025891754
C36: Telcel | D36: ='03-2026'!F17 -> 1946.99 | E36: =D36/$D$3 -> 0.00035760899 | F36: =D36/$D$4 -> 0.0012803299 | G36: ='04-2026'!F14 -> 1946.99 | H36: =G36/G$3 -> 0.00039052474 | I36: =G36/G$4 -> 0.0010769334 | J36: ='05-2026'!F12 -> 1946.99 | K36: =J36/J$3 -> 0.00065648099 | L36: =J36/J$4 -> 0.0018003281
C37: Abarrotes Raul | D37: ='03-2026'!F27 -> 11975.96 | E37: =D37/$D$3 -> 0.0021996574 | F37: =D37/$D$4 -> 0.0078753253 | G37: ='03-2026'!I27 -> 0 | H37: =G37/G$3 -> 0 | I37: =G37/G$4 -> 0 | J37: ='05-2026'!F18 -> 6053.59 | K37: =J37/J$3 -> 0.0020411336 | L37: =J37/J$4 -> 0.0055975881
C38: Xpertas | G38: ='04-2026'!F18 -> 8096.8 | H38: =G38/G$3 -> 0.0016240457 | I38: =G38/G$4 -> 0.0044785613 | J38: ='03-2026'!L28 -> 0 | K38: =J38/J$3 -> 0 | L38: =J38/J$4 -> 0
C39: Mac Store | G39: ='04-2026'!F11 -> 20399 | H39: =G39/G$3 -> 0.0040916051 | I39: =G39/G$4 -> 0.011283244 | J39: ='03-2026'!L29 -> 0 | K39: =J39/J$3 -> 0 | L39: =J39/J$4 -> 0
C40: Abasteo | J40: ='05-2026'!F2 -> 49126 | K40: =J40/J$3 -> 0.016564176 | L40: =J40/J$4 -> 0.04542546
B42: Marketing | D42: =SUM(D43:D48) -> 1705089.2 | E42: =D42/$D$3 -> 0.31317841 | F42: =D42/$D$4 -> 1.1212573 | G42: =SUM(G43:G48) -> 2590555.6 | H42: =G42/G$3 -> 0.5196103 | I42: =G42/G$4 -> 1.4329071 | J42: =SUM(J43:J48) -> 1719281.3 | K42: =J42/J$3 -> 0.57970277 | L42: =J42/J$4 -> 1.5897721
C43: Retorno Digital | D43: ='03-2026'!F9 -> 101500 | E43: =D43/$D$3 -> 0.018642783 | F43: =D43/$D$4 -> 0.066745841 | G43: ='04-2026'!F3 -> 101500 | H43: =G43/G$3 -> 0.020358739 | I43: =G43/G$4 -> 0.056142424 | J43: ='05-2026'!F4 -> 101500 | K43: =J43/J$3 -> 0.034223504 | L43: =J43/J$4 -> 0.093854257
C44: Google | D44: ='03-2026'!F10 -> 143953.31 | E44: =D44/$D$3 -> 0.026440299 | F44: =D44/$D$4 -> 0.094662904 | G44: ='04-2026'!F26+'04-2026'!F24 -> 250116.98 | H44: =G44/G$3 -> 0.050168141 | I44: =G44/G$4 -> 0.13834654 | J44: ='05-2026'!F25 -> 304217.56 | K44: =J44/J$3 -> 0.10257528 | L44: =J44/J$4 -> 0.28130161
...

Sheet Glossary
B2: Payee | C2: Category | D2: Short description (business view)
B3: EGT | C3: Platform & aggregation | D3: Game platform and aggregation fees.
B4: Amusnet | C4: Game provider | D4: Game content
B5: Nuvei | C5: Payment provider | D5: Funding of Nuvei payment processing account (deposits/withdrawals processing).
B6: STP | C6: Payment provider | D6: Monthly gateway fee to STP payment processor (April 2026).
B7: Bankaool | C7: Bank | D7: Provides the virtual cards used to pay Meta, Twilio etc.
B8: ACE | C8: Tax / fiscal services | D8: ACE is a SAT‑authorized PSA provider handling Mexican tax compliance and filings (tax technology/intermediary).
B9: ALDA | C9: Legal / tax advisory | D9: Professional services to obtain reduced gaming tax rate authorizations and similar fiscal rulings.
B10: Limon | C10: Accounting & advisory | D10: Ongoing accounting, tax compliance, and reporting firm (monthly fees by period).
B11: Federal Taxes / Gaming Taxes | C11: Taxes | D11: Federal gaming tax payments to SAT for the relevant month (February, March, April).
B12: ISR | C12: Taxes | D12: Income tax (ISR) payments to SAT.
B13: ISN | C13: Payroll taxes | D13: State payroll tax (Impuesto Sobre Nóminas).
... B32: Skywindgroup | C32: Game provider | D32: Game content

Sheet Payment+Assesment
B2: KPI | C2: Apr-26 Nuvei SPEI | D2: May-26 STP Direct
B3: Volume | C3: $5.47M | D3: $5.72M
B4: Transactions | C4: 11801 | D4: 10070
B5: Effective Fee | C5: 0.0336 | D5: 0.0074
B6: Cost per Transaction | C6: 15.56 | D6: 4.21
B9: Month | C9: Gateway | D9: Processed Volume (MXN) | E9: Transactions | F9: Processing Cost (MXN) | G9: Effective Fee
B10: 46320 | C10: Cards | D10: 32950 | E10: 147 | F10: 4258 | G10: 0.1292
B11: 46320 | C11: Nuvei SPEI | D11: 332683 | E11: 2368 | F11: 22989 | G11: 0.0691
B12: 46351 | C12: Cards | D12: 33748 | E12: 168 | F12: 4327 | G12: 0.1282
B13: 46351 | C13: Nuvei SPEI | D13: 286884 | E13: 1895 | F13: 30029 | G13: 0.1047
B14: 46381 | C14: Cards | D14: 125194 | E14: 779 | F14: 15223 | G14: 0.1216
B15: 46381 | C15: Nuvei SPEI | D15: 1223240 | E15: 5503 | F15: 62755 | G15: 0.0513
B16: 46048 | C16: Cards | D16: 212247 | E16: 811 | F16: 20185 | G16: 0.0951
B17: 46048 | C17: Nuvei SPEI | D17: 2042565 | E17: 8871 | F17: 101322 | G17: 0.0496
B18: 46079 | C18: Cards | D18: 335675 | E18: 1121 | F18: 28745 | G18: 0.0856
B19: 46079 | C19: Nuvei SPEI | D19: 3092861 | E19: 10972 | F19: 143149 | G19: 0.0463
B20: 46107 | C20: Cards | D20: 551006 | E20: 1108 | F20: 36168 | G20: 0.0656
B21: 46107 | C21: Nuvei SPEI | D21: 4134853 | E21: 9115 | F21: 149204 | G21: 0.0361
... B23: 46138 | C23: Nuvei SPEI | D23: 5467913 | E23: 11801 | F23: 183619 | G23: 0.0336
B24: 46168 | C24: Cards | D24: 1055033 | E24: 1519 | F24: Pending | G24: Pending
B25: 46168 | C25: Nuvei SPEI | D25: 1832333 | E25: 3843 | F25: Pending | G25: Pending
B26: 46168 | C26: STP Direct | D26: 5719981 | E26: 10070 | F26: 42428 | G26: 0.0074

Sheet 03-2026
C3: DESCRIPTION | D3: clabe | E3: Payment due date | F3: week 1 & 2
B4: Payroll | C4: Employee Termination | D4: clabe: '021320066284876685 | E4: 3.3.2026 | F4: 6435.06
B5: My affiliates | C5: Affiliates - Monthly service fee FEB | D5: account: 06200015752316 SWIFT: CTBAAU2S | E5: 13.3.2026 | F5: 32400
B6: FONACOT | C6: Mexican government credit institute for workers | D6: clabe: 002180026669411987 ref: 2330915 | E6: 6.3.2026 | F6: 877
B7: Limpieza Renovadora | C7: Office cleaning service – monthly fee | D7: cuenta: 014320655034105199 | E7: 13.3.2026 | F7: 19258.04
B8: ACE | C8: ACE SAT-authorized Service Providers PSA | D8: clabe: 014650655098789205 | E8: 13.3.2026 | F8: 35215.79
B9: Retorno Digital | C9: Marketing Agency fee Monthly Services invoice 8729 | D9: cuenta: 0110244198 | E9: 13.3.2026 | F9: 101500
B10: Google | C10: Google Ads Campaigns | D10: clabe: 124180002321680136 Ref: 5512143168 | E10: 13.3.2026 | F10: 143953.31
B11: Federal Taxes | C11: Payment of Gaming taxes february 2026 | D11: clabe: 147150000000447793 | E11: 10.3.2026 | F11: 102569.31
B12: Cris Matus | C12: Reimbursement (Twilio) | E12: 10.3.2026 | F12: 133450.52
B13: Cris Matus | C13: Reimbursement (META) | E13: 10.3.2026 | F13: 133370.68
B14: Vanguardia IT | C14: Monthly trunk line service | D14: CLABE 072135002268718996 | E14: 13.3.2026 | F14: 280.01
B15: ALDA | C15: ALDA ( Professional fees for obtaining tax rate reduction authorization) | D15: clabe: 058650000002386810 | E15: 13.3.2026 | F15: 64759.11
B16: Nuvei | C16: Nuvei Account Funding | D16: cuenta: 0123421260 | E16: 9.3.2026 | F16: 500000
B17: Telcel | C17: VIP mobile phone lines | D17: CONVENIO: 182251 REF: 0505581203708 | E17: 13.2.2026 | F17: 1946.99
B18: Rent | C18: Rent March 2026 | E18: 13.3.2026 | F18: 148048.48
B19: Maintenance | C19: Maintenance March 2026 | E19: 13.3.2026 | F19: 29609.7
B20: ISN | C20: Payroll Tax | E20: 13.3.2026 | F20: 37873
B21: SIPARE | C21: IMSS employer social security contributions | E21: 13.3.2026 | F21: 344559.64
B22: Payroll | C22: 1st Half of March 2026 Payroll (1 new CS agent missing from the PDF, added manually to the net amount) | E22: 13.3.2026 | F22: 447958.1
F23: 2284064.7
C25: DESCRIPTION | D25: clabe | E25: Payment due date | F25: week 1 & 2
B26: Payroll | C26: 2nd Half of March 2026 Payroll | E26: 29.3.2026 | F26: 452464.84
B27: Abarrotes Raul | C27: Coffee machine supplies | D27: convenio: 1397753 referencia: 622068 | F27: 11975.96
B28: ISN | C28: Payroll Tax | F28: 291797
B29: ISN | C29: Payroll Tax | F29: 13
B30: Eugenia Uvalle | C30: Reimbursement IMPI payments (5 invoices) (Brand registration) | D30: CLABE: 002180701862223080 | E30: 29.3.2026 | F30: 14068.85
B35: Cris Matus | C35: Reimbursement (Meta) | E35: 29.3.2026 | F35: 430499.42
B36: Cris Matus | C36: Reimbursement (Twilio) | E36: 29.3.2026 | F36: 193936.09
B37: Vanguardia IT | C37: Monthly trunk line service | D37: CLABE 072135002268718996 | E37: 29.3.2026 | F37: 2500.01
B38: PUBSA | C38: First month digital campaignInvoice 12286 | E38: 29.3.2026 | F38: 535979.16
B39: Limon | C39: Accounting firm- Monthly fee (Jan 25) | D39: cuenta: 002180026668799480 | E39: 29.3.2026 | F39: 45825.8
B40: EGT | D40: IBAN: BG65BGUS91601411774200 | E40: 15.6.2026 | F40: 641988.9
D41: SWIFT: BGUSBGSF

Sheet 04-2026
B2: ACE | C2: ACE SAT-authorized Service Providers PSA invoice 1193 | D2: clabe: 014650655098789205 | E2: 15.4.2026 | F2: 53042
B3: Retorno Digital | C3: Marketing Agency fee Monthly Services invoice 8758 | D3: cuenta: 0110244198 | E3: 15.4.2026 | F3: 101500
B4: My affiliates | C4: Affiliates - Monthly service fee MAR 21278 | D4: account: 06200015752316 SWIFT: CTBAAU2S | E4: 15.4.2026 | F4: 32400
B5: Vanguardia IT | C5: Monthly trunk line service 4044 | D5: CLABE 072135002268718996 | E5: 15.4.2026 | F5: 280.01
B6: Limpieza Renovadora | C6: Office cleaning service – monthly fee 18588 | D6: cuenta: 014320655034105199 | E6: 15.4.2026 | F6: 22111.08
B7: Gaming Taxes | C7: Payment of Gaming taxes march 2026 | D7: clabe: 147150000000447793 | E7: 10.4.2026 | F7: 119986.02
B8: ALDA | C8: ALDA ( Professional fees for obtaining tax rate reduction authorization) 5608 | D8: clabe: 058650000002386810 | E8: 15.4.2026 | F8: 65083.96
B9: Limon | C9: Accounting firm- Monthly fee (Dic 25) | D9: cuenta: 002180026668799480 | E9: 15.4.2026 | F9: 88448.84
B10: Amusnet | C10: Fees February 2026 | D10: ES6001822326510201551937 Swift :BBVAESMM | E10: 15.4.2026 | F10: 11000
B11: Mac Store | C11: laptop | D11: cuenta: 0143047288 | E11: 15.4.2026 | F11: 20399
B12: ISN | C12: Payroll Tax | D12: ´002180026669411987 REF: 2330915 | E12: 15.4.2026 | F12: 36614
B13: SIPARE | C13: IMSS employer social security contributions | D13: ´002180026669411987 REF: 2330915 | E13: 15.4.2026 | F13: 79155.44
... B16: Espacio Minerva | C16: Office maintenance | D16: clabe: 002320700177036231 | E16: 15.4.2026 | F16: 29609.7
B17: Payroll | C17: 1st Half of April 2026 Payroll | E17: 15.4.2026 | F17: 433242.74
B18: Xpertas | C18: Expense for office safety signage and fire extinguishers | D18: clabe: 021320065287144755 | E18: 15.4.2026 | F18: 8096.8
B19: inbet KLU | C19: 1st Half of April 2026 Payroll ( fund KLU) | E19: 15.4.2026 | F19: 350000
B23: Cris Matus | C23: Reimbursement (Twilio) | E23: 22.4.2026 | F23: 138686
B24: Cris Matus | C24: Reimbursement (Google Cloud) | E24: 22.4.2026 | F24: 1605.73
B25: ISR | C25: Tax | D25: ´002180026669411987 REF: 2330915 | E25: 22.4.2026 | F25: 280504
B26: Google | C26: Google Ads Campaigns | D26: clabe: 124180002321680136 Ref: 5541975269 | E26: 30.4.2026 | F26: 248511.25
B27: Cris Matus | C27: Reimbursement (Meta) | E27: 30.4.2026 | F27: 632393.33
B28: Cris Matus | C28: Reimbursement (Twilio) | E28: 30.4.2026 | F28: 149985.87
B29: Limon | C29: Accounting firm- Monthly fee (FEB 2026) 11591 | D29: cuenta: 002180026668799480 | E29: 30.4.2026 | F29: 43907.16
B30: Limon | C30: Accounting firm- Monthly fee (MAR 2026) 11601 | D30: cuenta: 002180026668799480 | E30: 30.4.2026 | F30: 42311
B31: Payroll | C31: 2nd Half of April 2026 Payroll | E31: 30.4.2026 | F31: 439322.47
B32: PUBSA | C32: digital campaign Invoice 12440 | D32: Cuenta: 0185224160 | E32: 30.4.2026 | F32: 535473.4
B33: Bankaool | C33: Bankaool Account Funding (META TWILIO VIRTUAL CARD) | E33: 30.4.2026 | F33: 750000

Sheet 05-2026
B2: Abasteo | C2: IT Office supplies ( Monitor Dell U2724DE LCD 27") 3Q Laptop , Disco Duro | D2: Convenio CIE: 1235036 | E2: 15.5.2026 | F2: 49126
B3: Vanguardia IT | C3: Monthly trunk line service 4044 14352 | D3: CLABE 072135002268718996 | E3: 15.5.2026 | F3: 280.01
B4: Retorno Digital | C4: Marketing Agency fee Monthly Services invoice 8778 | D4: cuenta: 0110244198 clabe : 012320001102441988 | E4: 15.5.2026 | F4: 101500
B5: ACE | C5: ACE SAT-authorized Service Providers PSA invoice 1251 | D5: clabe: 014650655098789205 | E5: 15.5.2026 | F5: 55000
B6: ALDA | C6: ALDA ( Professional fees for obtaining tax rate reduction authorization) 5674 | D6: clabe: 058650000002386810 | E6: 15.5.2026 | F6: 63988.12
B7: Gaming Taxes | C7: Payment of Gaming taxes april 2026 | D7: clabe: 147150000000447793 | E7: 10.5.2026 | F7: 126339.53
B8: Espacio Minerva | C8: Office Rent 5333 | D8: clabe: 030320900006212752 | E8: 15.5.2026 | F8: 148048.48
B9: Espacio Minerva | C9: Office maintenance 5334 | D9: clabe: 002320700177036231 | E9: 15.5.2026 | F9: 29609.7
B10: STP | C10: gateway fee monthly April 2026 | D10: clabe: 646180525500000000 | E10: 15.5.2026 | F10: 800.4
B11: Payroll | C11: 1st Half of May 2026 Payroll | E11: 15.5.2026 | F11: 443374.29
B12: Telcel | C12: VIP mobile phone lines | D12: CONVENIO: 182251 REF: 0505581203708 | E12: 15.5.2026 | F12: 1946.99
B13: ISN | C13: Payroll Tax | D13: ´002180026669411987 REF: 2330915 | E13: 15.5.2026 | F13: 35365
B14: SIPARE | C14: IMSS employer social security contributions | D14: ´002180026669411987 REF: 2330915 | E14: 15.5.2026 | F14: 363067.59
B15: Bankaool | C15: Bankaool Account Funding (META TWILIO VIRTUAL CARD) | E15: 15.5.2026 | F15: 250000
B16: Bankaool | C16: Bankaool Account Funding (META TWILIO VIRTUAL CARD) | E16: 15.5.2026 | F16: 250000
B17: Limpieza Renovadora | C17: Office cleaning service – monthly fee 18588 | D17: cuenta: 014320655034105199 | E17: 15.5.2026 | F17: 20684.56
B18: Abarrotes Raul | C18: Coffee machine supplies | D18: convenio: 1397753 referencia: 622068 | E18: 15.5.2026 | F18: 6053.59
B21: Bankaool | C21: Bankaool Account Funding (META TWILIO VIRTUAL CARD) | E21: 18.5.2026 | F21: 250000
B22: Bankaool | C22: Bankaool Account Funding (META TWILIO VIRTUAL CARD) | E22: 24.5.2026 | F22: 150000
B23: ISR | C23: Tax | D23: ´002180026669411987 REF: 2330915 | E23: 20.5.2026 | F23: 274447
B24: Notary | C24: Notarial expenses for the notarization of Deed No. 3140 | D24: Clabe: 012180001192833665 | E24: 30.5.2026 | F24: 18098
B25: Google | C25: Google Ads Campaigns | D25: clabe: 124180002321680136 Ref: 5569074280 | E25: 30.5.2026 | F25: 304217.56
B26: PUBSA | C26: digital campaign Invoice 12537 | D26: Cuenta: 0185224160 | E26: 30.5.2026 | F26: 413563.75
B27: Payroll | C27: 2nd Half of May 2026 Payroll | E27: 30.5.2026 | F27: 457938.76
B28: Notary | C28: notarization and formalization of the resolution for contributions. 1247 | D28: clabe: 014180220009375969 | E28: 30.5.2026 | F28: 233250
